<?xml version="1.0"?>

<robot name="trooper">

<!-- Color materials (Compatible with Rviz but not yet with Gazebo) -->
	<material name="greenish">
		<color rgba="0 0.612 0.306 1"/>
	</material>
	 
	<material name="whiteish">
		<color rgba="1 1 0.98 1"/>
	</material>

	<material name="rubber">
		<color rgba="0.1 0.1 0.1 1"/>
	</material>


<!-- LINKS -->

<!-- CHASSIS -->  
	<link name="trooper__chassis">
    <inertial>
      <mass value="40"/>
      <origin rpy="0  0  0" xyz="0  0  0"/>
      <inertia ixx="1.0" ixy="0.0" ixz="0.0" iyy="1.0" iyz="0.0" izz="1.0"/>
    </inertial>
    <collision>
      <origin rpy="0  0  0" xyz="0    0    0"/>
      <geometry>
        <mesh filename="package://trooper/meshes/stl/chassis.stl" scale="0.01 0.01 0.01"/>
      </geometry>
    </collision>
    <visual>
      <origin rpy="0  0  0" xyz="0    0    0"/>
      <geometry>
        <mesh filename="package://trooper/meshes/stl/chassis.stl" scale="0.01 0.01 0.01"/>
      </geometry>
			<material name="whiteish"/>
    </visual>
  </link>

	<gazebo reference="trooper__chassis">
		<material>Gazebo/White</material>
	</gazebo>




<!-- DRIVE WHEEL -->

  <link name="trooper__left_wheel">
    <inertial>
      <mass value="1"/>
      <origin rpy="0  0  0" xyz="0  0  0"/>
      <inertia ixx="1.0" ixy="0.0" ixz="0.0" iyy="1.0" iyz="0.0" izz="1.0"/>
    </inertial>
    <collision>
      <origin rpy="1.5707  0  0" xyz="0  0  0"/>
      <geometry>
        <cylinder radius="0.15" length="0.1" />
      </geometry>
    </collision>
    <visual>
      <origin rpy="0  0  0" xyz="0  0  0"/>
      <geometry>
        <mesh filename="package://trooper/meshes/stl/drive_wheel.stl" scale="0.01 0.01 0.01"/>
      </geometry>
			<material name="rubber"/>
    </visual>
  </link>

	<!-- Set PID coeff for left wheel -->
	<gazebo reference="trooper__left_wheel">
		<material>Gazebo/Grey </material>
		<mu1 value="200"/>
		<mu2 value="100"/>
		<kp value="10000000.0" />
		<kd value="1.0" />
		<maxVel>0.0</maxVel>
		<minDepth>0.001</minDepth>
	</gazebo>


  <link name="trooper__right_wheel">
    <inertial>
      <mass value="1"/>
      <origin rpy="0  0  0" xyz="0  0  0"/>
      <inertia ixx="1.0" ixy="0.0" ixz="0.0" iyy="1.0" iyz="0.0" izz="1.0"/>
    </inertial>
    <collision>
      <origin rpy="1.5707  0  0" xyz="0  0  0"/>
      <geometry>
        <cylinder radius="0.15" length="0.1" />
      </geometry>
    </collision>
    <visual>
      <origin rpy="0  0  0" xyz="0  0  0"/>
      <geometry>
        <mesh filename="package://trooper/meshes/stl/drive_wheel.stl" scale="0.01 0.01 0.01"/>
      </geometry>
			<material name="rubber"/>
    </visual>
  </link>

	<!-- Set PID coeff for right wheel -->
	<gazebo reference="trooper__right_wheel">
		<material>Gazebo/Grey </material>
		<mu1 value="200"/>
		<mu2 value="100"/>
		<kp value="10000000.0" />
		<kd value="1.0" />
		<maxVel>0.0</maxVel>
		<minDepth>0.001</minDepth>
	</gazebo>


  <link name="trooper__rim">
    <origin rpy="0.0 0.0 0.0" xyz="0.0 0.0 0.0" />
    <visual>
      <geometry>
        <cylinder radius="0.06" length="0.74" />
      </geometry>
    </visual>
  </link>

	<gazebo reference="trooper__rim">
		<material>Gazebo/Red</material>
	</gazebo>





<!-- PLATFORM -->
  <link name="trooper__platform">
    <inertial>
      <mass value="10"/>
      <origin rpy="0  0  0" xyz="0  0  0"/>
      <inertia ixx="1.0" ixy="0.0" ixz="0.0" iyy="1.0" iyz="0.0" izz="1.0"/>
    </inertial>
    <collision>
      <origin rpy="0  0  0" xyz="0.09  0    0"/>
      <geometry>
        <mesh filename="package://trooper/meshes/stl/platform_5x4L.stl" scale="0.01 0.01 0.01"/>
      </geometry>
    </collision>
    <visual>
      <origin rpy="0  0  0" xyz="0.09  0    0"/>
      <geometry>
        <mesh filename="package://trooper/meshes/stl/platform_5x4L.stl" scale="0.01 0.01 0.01"/>
      </geometry>
			<material name="greenish"/>
    </visual>
  </link>

	<gazebo reference="trooper__platform">
		<material>Gazebo/Green</material>
	</gazebo>




<!-- SENSORS -->
  <link name="trooper__hokuyo__link">
    <inertial>
      <mass value="0.1"/>
      <origin rpy="0  0  0" xyz="0  0  0"/>
      <inertia ixx="1" ixy="0" ixz="0" iyy="1" iyz="0" izz="1"/>
    </inertial>
    <collision>
      <origin rpy="0  0  0" xyz="0      0     -0.0145"/>
      <geometry>
        <box size="0.05 0.05 0.041"/>
      </geometry>
    </collision>
    <collision>
      <origin rpy="0  0  0" xyz="0      0      0.0205"/>
      <geometry>
        <cylinder length="0.029" radius="0.021"/>
      </geometry>
    </collision>
    <visual>
      <origin rpy="0  0  0" xyz="0  0  0"/>
      <geometry>
        <box size="0.05 0.05 0.041"/>
      </geometry>
    </visual>
  </link>




<!-- JOINTS -->  

	<joint name="trooper__left_wheel_to_chassis" type="continuous">
    <parent link="trooper__chassis"/>
    <child link="trooper__left_wheel"/>
    <origin rpy="1.5707  1.5707  1.5707" xyz="0.14  0.33  0.15"/>
    <axis xyz="0   1   0"/>
    <limit effort="50" velocity="100"/>
		<dynamics damping="0.7" friction="100" />
  </joint>

 	<joint name="trooper__right_wheel_to_chassis" type="continuous">
    <parent link="trooper__chassis"/>
    <child link="trooper__right_wheel"/>
    <origin rpy="1.5707 -1.5707  1.5707" xyz="0.14 -0.33  0.15"/>
    <axis xyz="0  -1  0"/>
    <limit effort="50" velocity="100"/>
		<dynamics damping="0.7" friction="100" />
  </joint>


	<joint name="trooper__rim_to_chassis" type="fixed">
    <parent link="trooper__chassis"/>
    <child link="trooper__rim"/>
    <origin rpy="1.5707 0 0" xyz="0.14 0 0.15"/>
    <axis xyz="0 0 0"/>
  </joint>


	<joint name="trooper__platform_to_chassis" type="continuous">
    <parent link="trooper__chassis"/>
    <child link="trooper__platform"/>
    <origin rpy="0  0  1.5707" xyz="0  0  0.55"/>
    <axis xyz="0  0  1"/>
    <limit effort="10" velocity="100"/>
  </joint>


	<joint name="trooper__hokuyo_joint" type="fixed">
    <parent link="trooper__chassis"/>
    <child link="trooper__hokuyo__link"/>
    <origin rpy="0  0  0" xyz="0.2    0     0.115"/>
    <axis xyz="0  0  0"/>
  </joint>




<!--  GAZEBO plugin for ROS Control -->
	<gazebo>
		<plugin name="gazebo_ros_control" filename="libgazebo_ros_control.so">
		<robotNamespace>/</robotNamespace>
		</plugin>
	</gazebo>



<!-- TRANSMISSIONS -->
  <transmission name="trooper__platform_to_chassis_trans">
    <type>transmission_interface/SimpleTransmission</type>
    <actuator name="trooper__platform_state">
      <mechanicalReduction>1</mechanicalReduction>
    </actuator>
    <joint name="trooper__platform_to_chassis">
      <hardwareInterface>PositionJointInterface</hardwareInterface>
    </joint>
  </transmission>

  <transmission name="trooper__left_wheel_to_chassis_trans">
    <type>transmission_interface/SimpleTransmission</type>
    <actuator name="trooper__left_wheel_state">
      <mechanicalReduction>1</mechanicalReduction>
    </actuator>
    <joint name="trooper__left_wheel_to_chassis">
      <hardwareInterface>VelocityJointInterface</hardwareInterface>
    </joint>
  </transmission>

  <transmission name="trooper__right_wheel_to_chassis_trans">
    <type>transmission_interface/SimpleTransmission</type>
    <actuator name="trooper__right_wheel_state">
      <mechanicalReduction>1</mechanicalReduction>
    </actuator>
    <joint name="trooper__right_wheel_to_chassis">
      <hardwareInterface>VelocityJointInterface</hardwareInterface>
    </joint>
  </transmission>




</robot>



