<?xml version="1.0"?>
<robot name="trooper" xmlns:xacro="http://ros.org/wiki/xacro">
	<xacro:property name="M_PI" value="3.1415926535897931" />
	<xacro:arg name="gpu" default="false"/>
	<xacro:property name="gpu" value="$(arg gpu)" />
 	<xacro:arg name="organize_cloud" default="true"/>
 	<xacro:property name="organize_cloud" value="$(arg organize_cloud)" />

<!-- Color materials (Compatible with Rviz but not yet with Gazebo) -->
	<material name="greenish">
		<color rgba="0 0.612 0.306 1"/>
	</material>

	<material name="whiteish">
		<color rgba="1 1 0.98 1"/>
	</material>

	<material name="rubber">
		<color rgba="0.1 0.1 0.1 1"/>
	</material>


<!-- LINKS -->

<!-- CHASSIS -->
<!--
<link name="dummy">
   </link>
-->

	<link name="base_link">
    <inertial>
      <mass value="40"/>
      <origin rpy="0  0  0" xyz="0  0  0"/>
      <inertia ixx="1.0" ixy="0.0" ixz="0.0" iyy="1.0" iyz="0.0" izz="1.0"/>
    </inertial>
    <collision>
      <origin rpy="0  0  0" xyz="0    0    0"/>
      <geometry>
        <mesh filename="package://trooper_description/meshes/stl/chassis.stl" scale="0.01 0.01 0.01"/>
      </geometry>
    </collision>
    <visual>
      <origin rpy="0  0  0" xyz="0    0    0"/>
      <geometry>
        <mesh filename="package://trooper_description/meshes/stl/chassis.stl" scale="0.01 0.01 0.01"/>
      </geometry>
			<material name="whiteish"/>
    </visual>
  </link>

	<gazebo reference="base_link">
		<material>Gazebo/White</material>
	</gazebo>




<!-- DRIVE WHEEL -->

  <link name="trooper__left_wheel">
    <inertial>
      <mass value="1"/>
      <origin rpy="0  0  0" xyz="0  0  0"/>
      <inertia ixx="1.0" ixy="0.0" ixz="0.0" iyy="1.0" iyz="0.0" izz="1.0"/>
    </inertial>
    <collision>
      <origin rpy="1.5707  0  0" xyz="0  0  0"/>
      <geometry>
        <cylinder radius="0.15" length="0.1" />
      </geometry>
    </collision>
    <visual>
      <origin rpy="0  0  0" xyz="0  0  0"/>
      <geometry>
        <mesh filename="package://trooper_description/meshes/stl/drive_wheel.stl" scale="0.01 0.01 0.01"/>
      </geometry>
			<material name="rubber"/>
    </visual>
  </link>

	<!-- Set PID coeff for left wheel -->
	<gazebo reference="trooper__left_wheel">
		<material>Gazebo/Grey </material>
		<mu1 value="200"/>
		<mu2 value="100"/>
		<kp value="10000000.0" />
		<kd value="1.0" />
		<!--<maxVel>0.0</maxVel>
		<minDepth>0.001</minDepth>-->
	</gazebo>


  <link name="trooper__right_wheel">
    <inertial>
      <mass value="1"/>
      <origin rpy="0  0  0" xyz="0  0  0"/>
      <inertia ixx="1.0" ixy="0.0" ixz="0.0" iyy="1.0" iyz="0.0" izz="1.0"/>
    </inertial>
    <collision>
      <origin rpy="1.5707  0  0" xyz="0  0  0"/>
      <geometry>
        <cylinder radius="0.15" length="0.1" />
      </geometry>
    </collision>
    <visual>
      <origin rpy="0  0  0" xyz="0  0  0"/>
      <geometry>
        <mesh filename="package://trooper_description/meshes/stl/drive_wheel.stl" scale="0.01 0.01 0.01"/>
      </geometry>
			<material name="rubber"/>
    </visual>
  </link>

	<!-- Set PID coeff for right wheel -->
	<gazebo reference="trooper__right_wheel">
		<material>Gazebo/Grey </material>
		<mu1 value="200"/>
		<mu2 value="100"/>
		<kp value="10000000.0" />
		<kd value="1.0" />
		<!--<maxVel>0.0</maxVel>
		<minDepth>0.001</minDepth>-->
	</gazebo>


  <link name="trooper__rim">
    <origin rpy="0.0 0.0 0.0" xyz="0.0 0.0 0.0" />
    <visual>
      <geometry>
        <cylinder radius="0.06" length="0.74" />
      </geometry>
    </visual>
  </link>

	<gazebo reference="trooper__rim">
		<material>Gazebo/Red</material>
	</gazebo>





<!-- magasin -->
  <link name="trooper__magasin">
    <inertial>
      <mass value="3"/>
      <origin rpy="0  0  0" xyz="0  0  0"/>
      <inertia ixx="1.0" ixy="0.0" ixz="0.0" iyy="1.0" iyz="0.0" izz="1.0"/>
    </inertial>
    <collision>
      <origin rpy="0  0  0" xyz="0.09  0    0"/>
      <geometry>
        <mesh filename="package://trooper_description/meshes/stl/magasin_5x4L.stl" scale="0.01 0.01 0.01"/>
      </geometry>
    </collision>
    <visual>
      <origin rpy="0  0  0" xyz="0.09  0    0"/>
      <geometry>
        <mesh filename="package://trooper_description/meshes/stl/magasin_5x4L.stl" scale="0.01 0.01 0.01"/>
      </geometry>
			<material name="greenish"/>
    </visual>
  </link>

	<gazebo reference="trooper__magasin">
		<material>Gazebo/Green</material>
	</gazebo>





<!-- SENSORS -->
<!--
	<link name="lidar">
		<collision>
		  <origin xyz="0 0 0" rpy="0 0 0"/>
		  <geometry>
		    <box size="0.05 0.05 0.041"/>
		  </geometry>
		</collision>
		<visual>
		  <origin xyz="0 0 0" rpy="0 0 0"/>
		  <geometry>
		    <cylinder length="0.029" radius="0.021"/>
		  </geometry>
		</visual>
		<inertial>
		  <mass value="0.1" />
		  <origin xyz="0 0 0" rpy="0 0 0"/>
		  <inertia ixx="1" ixy="0" ixz="0" iyy="1" iyz="0" izz="1" />
		</inertial>
	</link>
	-->

<link name="imu_link">
  <inertial>
    <mass value="0.001"/>
    <origin rpy="0 0 0" xyz="0 0 0"/>
    <inertia ixx="0.0001" ixy="0" ixz="0" iyy="0.000001" iyz="0" izz="0.0001"/>
  </inertial>
  <visual>
    <origin rpy="0 0 0" xyz="0 0 0"/>
    <geometry>
      <box size="0.001 0.001 0.001"/>
    </geometry>
  </visual>
  <collision>
    <origin rpy="0 0 0" xyz="0 0 0"/>
    <geometry>
      <box size=".001 .001 .001"/>
    </geometry>
  </collision>
</link>





<!-- JOINTS -->
<!--
<joint name="dummy_joint" type="fixed">
	 <parent link="dummy"/>
	 <child link="base_link"/>
 </joint>

 -->

	<joint name="trooper__left_wheel_to_chassis" type="continuous">
    <parent link="base_link"/>
    <child link="trooper__left_wheel"/>
    <origin rpy="1.5707  1.5707  1.5707" xyz="0.14  0.33  0.15"/>
    <axis xyz="0   1   0"/>
    <!--<limit effort="50" velocity="100"/>-->
		<dynamics damping="0.7" friction="100" />
  </joint>

 	<joint name="trooper__right_wheel_to_chassis" type="continuous">
    <parent link="base_link"/>
    <child link="trooper__right_wheel"/>
    <origin rpy="1.5707 -1.5707  1.5707" xyz="0.14 -0.33  0.15"/>
    <axis xyz="0  -1  0"/>
    <!--<limit effort="50" velocity="100"/>-->
		<dynamics damping="0.7" friction="100" />
  </joint>


	<joint name="trooper__rim_to_chassis" type="fixed">
    <parent link="base_link"/>
    <child link="trooper__rim"/>
    <origin rpy="1.5707 0 0" xyz="0.14 0 0.15"/>
    <axis xyz="0 0 0"/>
  </joint>

	<joint name="trooper__magasin_to_chassis" type="continuous">
    <parent link="base_link"/>
    <child link="trooper__magasin"/>
    <origin rpy="0  0  1.5707" xyz="0  0  0.55"/>
    <axis xyz="0  0  1"/>
    <!--<limit effort="10" velocity="100"/>-->
  </joint>

	<joint name="imu_joint" type="fixed">
		<axis xyz="1 0 0"/> <!-- 0 1 0 -->
		<origin xyz="0 0 0.19"/>
		<parent link="base_link"/>
		<child link="imu_link"/>
	</joint>

<!--
  <property name="lidar" value="0.15" />
  <joint name="lidar_joint" type="fixed">
    <axis xyz="0 1 0" />
    <origin xyz="0.28 0 0.08" rpy="0 0 0"/>
    <parent link="base_link"/>
    <child link="lidar"/>
  </joint>
-->

<!--
	<xacro:include filename="$(find velodyne_description)/urdf/VLP-16.urdf.xacro"/>
	<xacro:VLP-16 parent="lidar" name="velodyne" topic="/cloud" organize_cloud="${organize_cloud}" hz="10" samples="653" gpu="${gpu}" lasers="4" min_angle="-1.3955"
		max_angle="1.3955" min_range="0.10" max_range="5.0">
	<origin xyz="0.04 0 0" rpy="0 0 0" />
	</xacro:VLP-16>
-->

	<xacro:include filename="$(find velodyne_description)/urdf/VLP-16.urdf.xacro"/>
  <xacro:VLP-16 parent="base_link" name="lidar" topic="/cloud" organize_cloud="${organize_cloud}" hz="10" samples="653" gpu="${gpu}">
    <origin xyz="0.28 0 0.08" rpy="0 0 0"/>
  </xacro:VLP-16>



<!--  GAZEBO plugin for Laser -->
<!--
  <gazebo reference="lidar">
    <sensor type="ray" name="head_hokuyo_sensor">
      <pose>0 0 0 0 0 0</pose>
      <visualize>true</visualize>
      <update_rate>20</update_rate>
      <ray>
        <scan>
          <horizontal>
            <samples>653</samples>
            <resolution>1</resolution>
            <min_angle>-1.3955</min_angle>
            <max_angle>1.3955</max_angle>
          </horizontal>
					<vertical>
            <samples>4</samples>
            <min_angle>-0.065</min_angle>
            <max_angle>0.065</max_angle>
            <resolution>1</resolution>
          </vertical>
        </scan>
        <range>
          <min>0.10</min>
          <max>5.0</max>
          <resolution>0.01</resolution>
        </range>
        <noise>
          <type>gaussian</type>-->
          <!-- Noise parameters based on published spec for Hokuyo laser
               achieving "+-30mm" accuracy at range < 10m.  A mean of 0.0m and
               stddev of 0.01m will put 99.7% of samples within 0.03m of the true
               reading. -->
							   <!--
          <mean>0.0</mean>
          <stddev>0.01</stddev>
        </noise>
      </ray>
      <plugin name="velodyne_gazebo_plugins" filename="libgazebo_ros_laser.so">
        <topicName>/scan</topicName>
        <frameName>lidar</frameName>
      </plugin>
    </sensor>
  </gazebo>-->




<!--  GAZEBO plugin for IMU -->

  <gazebo reference="imu_link">
    <gravity>true</gravity>
    <sensor name="imu_sensor" type="imu">
      <always_on>true</always_on>
      <update_rate>100</update_rate>
      <visualize>true</visualize>
      <topic>__default_topic__</topic>
      <plugin filename="libgazebo_ros_imu_sensor.so" name="imu_plugin">
        <topicName>imu</topicName>
        <bodyName>imu_link</bodyName>
        <updateRateHZ>10.0</updateRateHZ>
        <gaussianNoise>0.0</gaussianNoise>
        <xyzOffset>0 0 0</xyzOffset>
        <rpyOffset>0 0 0</rpyOffset>
        <frameName>imu_link</frameName>
      </plugin>
      <pose>0 0 0 0 0 0</pose>
    </sensor>
  </gazebo>

<!--
	<gazebo>
		<controller:gazebo_ros_imu name="imu_controller" plugin="libgazebo_ros_imu.so">
		  <alwaysOn>true</alwaysOn>
		  <updateRate>50.0</updateRate>
		  <bodyName>imu_link</bodyName>
		  <topicName>/imu/data</topicName>
		  <gaussianNoise>2.89e-08</gaussianNoise>
		  <xyzOffsets>0 0 0</xyzOffsets>
		  <rpyOffsets>0 0 0</rpyOffsets>
		  <interface:position name="imu_position"/>
		</controller:gazebo_ros_imu>
	</gazebo>
-->






<!--  GAZEBO plugin for ROS Control -->
	<gazebo>
		<plugin name="gazebo_ros_control" filename="libgazebo_ros_control.so">
		<robotNamespace>/</robotNamespace>
		</plugin>
	</gazebo>



<!-- TRANSMISSIONS -->
  <transmission name="trooper__magasin_to_chassis_trans">
    <type>transmission_interface/SimpleTransmission</type>
    <actuator name="trooper__magasin_state">
      <mechanicalReduction>1</mechanicalReduction>
    </actuator>
    <joint name="trooper__magasin_to_chassis">
      <hardwareInterface>hardware_interface/PositionJointInterface</hardwareInterface>
    </joint>
  </transmission>

  <transmission name="trooper__left_wheel_to_chassis_trans">
    <type>transmission_interface/SimpleTransmission</type>
    <actuator name="trooper__left_wheel_state">
      <mechanicalReduction>1</mechanicalReduction>
    </actuator>
    <joint name="trooper__left_wheel_to_chassis">
      <hardwareInterface>hardware_interface/VelocityJointInterface</hardwareInterface>
    </joint>
  </transmission>

  <transmission name="trooper__right_wheel_to_chassis_trans">
    <type>transmission_interface/SimpleTransmission</type>
    <actuator name="trooper__right_wheel_state">
      <mechanicalReduction>1</mechanicalReduction>
    </actuator>
    <joint name="trooper__right_wheel_to_chassis">
      <hardwareInterface>hardware_interface/VelocityJointInterface</hardwareInterface>
    </joint>
  </transmission>




</robot>
